Workbook

Sheet Anleitung
B2: Nebenkostenabrechnung Gewerbe – Arbeitsmappe
B3: Vorlage für Vermieter / Kanzlei · Vertragsmatrix · Abrechnung · USt-Check
B5: 1. Stammdaten
B6: Objekt, Mieter, Abrechnungsjahr, USt-Option und Flächen eintragen.
B8: 2. Vertrags-Matrix
B9: Je Kostenart: laut Mietvertrag umlagefähig? Schlüssel? Bemerkung? Gelbe Felder = Eingabe.
B11: 3. Kosten erfassen
B12: Im Blatt „Kostenarten“ die Jahreskosten netto eintragen. Nicht umlagefähiges bleibt auf „Nein“.
B14: 4. Abrechnung
B15: Blatt „Abrechnung“ berechnet Anteile, USt und Saldo automatisch aus Stammdaten + Kostenarten + Vorauszahlungen.
B17: 5. Checkliste
B18: Vor Versand die Checkliste abhaken. Belege und Vertrag griffbereit halten.
... B24: Rot = nicht umlagefähig

Sheet Stammdaten
B2: Stammdaten Objekt & Mieter
B3: Gelbe Felder ausfüllen – die Abrechnung bezieht sich darauf.
B5: Objekt / Adresse | C5: Musterstraße 1, 80331 München
B6: Einheit / Fläche Mieter | C6: EG Laden / Büro
B7: Mieter (Firma) | C7: Muster Handel GmbH
B8: Mietvertragsdatum | C8: 01.01.2023
B9: Abrechnungszeitraum von | C9: 45658
B10: Abrechnungszeitraum bis | C10: 46022
B11: USt-Option Vermietung | C11: Ja
B12: USt-Satz | C12: 0.19
B13: Fläche Mieter m² | C13: 120
B14: Gesamtfläche Abrechnungseinheit m² | C14: 800
B15: Umlageschlüssel Standard | C15: Fläche
B16: Vorauszahlung NK / Monat netto | C16: 350
B17: Monate im Zeitraum | C17: 12
B19: Berechnet (nicht ändern)
B20: Flächenanteil Mieter | C20: =IF(C14=0,0,C13/C14)
B21: Vorauszahlung Zeitraum netto | C21: =C16*C17
B22: Vorauszahlung Zeitraum brutto (inkl. USt) | C22: =IF(C11="Ja",C21*(1+C12),C21)
B24: Hinweise
B25: • Bei USt-Option = Ja: Kostenarten netto erfassen; Abrechnung setzt USt auf den Mieteranteil.
B26: • Fläche Abrechnungseinheit = alle Flächen, auf die die Kosten verteilt werden (nicht immer das ganze Grundstück).
B27: • Weicht der Vertragsschlüssel je Kostenart ab, in Kostenarten/Vertrags-Matrix je Zeile setzen.

Sheet Vertrags-Matrix
B2: Vertrags-Matrix – Umlagefähigkeit laut Mietvertrag
B3: Vor der Abrechnung je Position klären. Nur „Ja“-Positionen fließen in die Abrechnung ein.
B5: Nr | C5: Kostenart | D5: Im Vertrag? | E5: Umlagefähig? | F5: Verteilerschlüssel | G5: Obergrenze € | H5: USt-relevant? | I5: Vertragsfundstelle / Klausel | J5: Bemerkung / Risiko
B6: 1 | C6: Grundsteuer | D6: Ja | E6: Ja | F6: Fläche | H6: Nein | I6: § … / BetrKV Nr. 1
B7: 2 | C7: Wasser / Abwasser | D7: Ja | E7: Ja | F7: Verbrauch | H7: Ja | J7: Zähler vorhanden?
B8: 3 | C8: Heizung / Warmwasser | D8: Ja | E8: Ja | F8: Verbrauch | H8: Ja | I8: HeizkostenV prüfen
B9: 4 | C9: Straßenreinigung / Müll | D9: Ja | E9: Ja | F9: Fläche | H9: Ja
B10: 5 | C10: Gebäudeversicherung | D10: Ja | E10: Ja | F10: Fläche | H10: Nein | J10: nur Gebäudeversicherung prüfen
B11: 6 | C11: Haftpflicht Gebäude | D11: Ja | E11: Ja | F11: Fläche | H11: Nein
B12: 7 | C12: Hausmeister / Facility | D12: Ja | E12: Ja | F12: Fläche | H12: Ja
B13: 8 | C13: Gartenpflege / Außenanlagen | D13: Ja | E13: Ja | F13: Fläche | H13: Ja
B14: 9 | C14: Aufzug Wartung | D14: Ja | E14: Ja | F14: Fläche | H14: Ja | J14: Wartung ≠ Reparatur
B15: 10 | C15: Aufzug Instandsetzung | D15: Nein | E15: Nein | F15: — | H15: Ja | J15: oft nicht / nur mit Obergrenze
B16: 11 | C16: Klima- / Lüftungsanlage Wartung | D16: Ja | E16: Ja | F16: Fläche | H16: Ja | J16: explizit benennen
B17: 12 | C17: Brandschutz / Sicherheitstechnik | D17: Ja | E17: Ja | F17: Fläche | H17: Ja
B18: 13 | C18: Sicherheit / Bewachung | D18: Ja | E18: Ja | F18: Fläche | H18: Ja
B19: 14 | C19: Reinigung Gemeinschaftsflächen | D19: Ja | E19: Ja | F19: Fläche | H19: Ja
B20: 15 | C20: Beleuchtung Allgemein | D20: Ja | E20: Ja | F20: Fläche | H20: Ja
B21: 16 | C21: Niederschlagswasser | D21: Ja | E21: Ja | F21: Fläche | H21: Nein
B22: 17 | C22: Verwaltungskosten | D22: Ja | E22: Ja | F22: Fläche | H22: Ja | I22: explizit im Vertrag? | J22: nur bei klarer Vereinbarung
B23: 18 | C23: Werbegemeinschaft / Center-Umlage | D23: Nein | E23: Nein | F23: — | H23: Ja | J23: nur wenn vereinbart
B24: 19 | C24: Instandhaltung pauschal | D24: Nein | E24: Nein | F24: — | H24: Ja | J24: AGB-Risiko – Obergrenze prüfen
B25: 20 | C25: Schornstein / Kehrgebühren | D25: Ja | E25: Ja | F25: Fläche | H25: Nein
B26: 21 | C26: Kabel / TV / Daten Gemeinschaft | D26: Nein | E26: Nein | F26: — | H26: Ja
B27: 22 | C27: WEG-Hausgeld umlagefähiger Anteil | D27: Ja | E27: Ja | F27: Fläche | H27: Nein | I27: WEG-Abrechnung splitten | J27: nicht 1:1 alles umlegen
B28: 23 | C28: Leerstandsanteil | D28: — | E28: Nein | F28: — | H28: — | J28: trägt Vermieter
B29: 24 | C29: Finanzierung / Zinsen / AfA | D29: — | E29: Nein | F29: — | H29: — | J29: nie Betriebskosten
B31: Leere Zeilen darunter für weitere vertragliche Positionen nutzen. Nach Vertragsprüfung anpassen.

Sheet Kostenarten
B2: Kostenarten – Jahreskosten erfassen
B3: Beträge netto eintragen (bei USt-Option). Spalte „Umlagefähig“ mit Vertrags-Matrix abgleichen. Beispielwerte sind vorausgefüllt.
B5: Nr | C5: Kostenart | D5: Umlagefähig? | E5: Gesamtkosten netto € | F5: davon nicht umlagefähig € | G5: Umlagefähiger Betrag € | H5: Schlüssel | I5: Anteil % / Faktor | J5: Beleg / Rechnung
B6: 1 | C6: Grundsteuer | D6: Ja | E6: 4800 | F6: 0 | G6: =IF(D6="Ja",MAX(0,E6-F6),0) | H6: Fläche | I6: =IF(H6="Fläche",Stammdaten!C20,0)
B7: 2 | C7: Wasser / Abwasser | D7: Ja | E7: 3200 | F7: 0 | G7: =IF(D7="Ja",MAX(0,E7-F7),0) | H7: Verbrauch | I7: 0.18
B8: 3 | C8: Heizung / Warmwasser | D8: Ja | E8: 14500 | F8: 0 | G8: =IF(D8="Ja",MAX(0,E8-F8),0) | H8: Verbrauch | I8: 0.18
B9: 4 | C9: Straßenreinigung / Müll | D9: Ja | E9: 2100 | F9: 0 | G9: =IF(D9="Ja",MAX(0,E9-F9),0) | H9: Fläche | I9: =IF(H9="Fläche",Stammdaten!C20,0)
B10: 5 | C10: Gebäudeversicherung | D10: Ja | E10: 3600 | F10: 0 | G10: =IF(D10="Ja",MAX(0,E10-F10),0) | H10: Fläche | I10: =IF(H10="Fläche",Stammdaten!C20,0)
B11: 6 | C11: Haftpflicht Gebäude | D11: Ja | E11: 900 | F11: 0 | G11: =IF(D11="Ja",MAX(0,E11-F11),0) | H11: Fläche | I11: =IF(H11="Fläche",Stammdaten!C20,0)
B12: 7 | C12: Hausmeister / Facility | D12: Ja | E12: 8400 | F12: 0 | G12: =IF(D12="Ja",MAX(0,E12-F12),0) | H12: Fläche | I12: =IF(H12="Fläche",Stammdaten!C20,0)
B13: 8 | C13: Gartenpflege / Außenanlagen | D13: Ja | E13: 1800 | F13: 0 | G13: =IF(D13="Ja",MAX(0,E13-F13),0) | H13: Fläche | I13: =IF(H13="Fläche",Stammdaten!C20,0)
B14: 9 | C14: Aufzug Wartung | D14: Ja | E14: 2400 | F14: 0 | G14: =IF(D14="Ja",MAX(0,E14-F14),0) | H14: Fläche | I14: =IF(H14="Fläche",Stammdaten!C20,0)
B15: 10 | C15: Aufzug Instandsetzung | D15: Nein | E15: 0 | F15: 0 | G15: =IF(D15="Ja",MAX(0,E15-F15),0) | H15: Fläche | I15: 0
B16: 11 | C16: Klima- / Lüftungsanlage Wartung | D16: Ja | E16: 3100 | F16: 0 | G16: =IF(D16="Ja",MAX(0,E16-F16),0) | H16: Fläche | I16: =IF(H16="Fläche",Stammdaten!C20,0)
B17: 12 | C17: Brandschutz / Sicherheitstechnik | D17: Ja | E17: 1500 | F17: 0 | G17: =IF(D17="Ja",MAX(0,E17-F17),0) | H17: Fläche | I17: =IF(H17="Fläche",Stammdaten!C20,0)
B18: 13 | C18: Sicherheit / Bewachung | D18: Ja | E18: 6000 | F18: 0 | G18: =IF(D18="Ja",MAX(0,E18-F18),0) | H18: Fläche | I18: =IF(H18="Fläche",Stammdaten!C20,0)
B19: 14 | C19: Reinigung Gemeinschaftsflächen | D19: Ja | E19: 4800 | F19: 0 | G19: =IF(D19="Ja",MAX(0,E19-F19),0) | H19: Fläche | I19: =IF(H19="Fläche",Stammdaten!C20,0)
B20: 15 | C20: Beleuchtung Allgemein | D20: Ja | E20: 2200 | F20: 0 | G20: =IF(D20="Ja",MAX(0,E20-F20),0) | H20: Fläche | I20: =IF(H20="Fläche",Stammdaten!C20,0)
B21: 16 | C21: Niederschlagswasser | D21: Ja | E21: 700 | F21: 0 | G21: =IF(D21="Ja",MAX(0,E21-F21),0) | H21: Fläche | I21: =IF(H21="Fläche",Stammdaten!C20,0)
B22: 17 | C22: Verwaltungskosten | D22: Ja | E22: 4200 | F22: 0 | G22: =IF(D22="Ja",MAX(0,E22-F22),0) | H22: Fläche | I22: =IF(H22="Fläche",Stammdaten!C20,0)
B23: 18 | C23: Werbegemeinschaft / Center-Umlage | D23: Nein | E23: 0 | F23: 0 | G23: =IF(D23="Ja",MAX(0,E23-F23),0) | H23: Fläche | I23: 0
B24: 19 | C24: Instandhaltung pauschal | D24: Nein | E24: 0 | F24: 0 | G24: =IF(D24="Ja",MAX(0,E24-F24),0) | H24: Fläche | I24: 0
B25: 20 | C25: Schornstein / Kehrgebühren | D25: Ja | E25: 350 | F25: 0 | G25: =IF(D25="Ja",MAX(0,E25-F25),0) | H25: Fläche | I25: =IF(H25="Fläche",Stammdaten!C20,0)
B26: 21 | C26: Kabel / TV / Daten Gemeinschaft | D26: Nein | E26: 0 | F26: 0 | G26: =IF(D26="Ja",MAX(0,E26-F26),0) | H26: Fläche | I26: 0
B27: 22 | C27: WEG-Hausgeld umlagefähiger Anteil | D27: Ja | E27: 9600 | F27: 0 | G27: =IF(D27="Ja",MAX(0,E27-F27),0) | H27: Fläche | I27: =IF(H27="Fläche",Stammdaten!C20,0)
B28: 23 | C28: Leerstandsanteil | D28: Nein | E28: 0 | F28: 0 | G28: =IF(D28="Ja",MAX(0,E28-F28),0) | H28: Fläche | I28: 0
B29: 24 | C29: Finanzierung / Zinsen / AfA | D29: Nein | E29: 0 | F29: 0 | G29: =IF(D29="Ja",MAX(0,E29-F29),0) | H29: Fläche | I29: 0
C30: SUMME | E30: =SUM(E6:E29) | F30: =SUM(F6:F29) | G30: =SUM(G6:G29)
B32: Bei Schlüssel „Verbrauch“ / „Nutzerzahl“ / „Mischschlüssel“: Spalte „Anteil % / Faktor“ manuell setzen (z. B. 0,18 für 18 %). Bei „Fläche“ greift automatisch Stammdaten.

Sheet Abrechnung
B2: Nebenkostenabrechnung Gewerbe
B3: Automatisch aus Stammdaten + Kostenarten. Vor Versand prüfen und an den Mieter senden.
B5: Objekt | C5: =Stammdaten!C5
B6: Mieter | C6: =Stammdaten!C7
B7: Einheit | C7: =Stammdaten!C6
B8: Zeitraum von | C8: =Stammdaten!C9
B9: Zeitraum bis | C9: =Stammdaten!C10
B10: Fläche Mieter m² | C10: =Stammdaten!C13
B11: Gesamtfläche m² | C11: =Stammdaten!C14
B12: Flächenanteil | C12: =Stammdaten!C20
B13: USt-Option | C13: =Stammdaten!C11
B15: Nr | C15: Kostenart | D15: Umlagefähig Gesamt € | E15: Schlüssel | F15: Anteil | G15: Anteil Mieter netto € | H15: USt € | I15: Brutto €
B16: 1 | C16: =Kostenarten!C6 | D16: =Kostenarten!G6 | E16: =Kostenarten!H6 | F16: =Kostenarten!I6 | G16: =Kostenarten!G6*Kostenarten!I6 | H16: =IF(Stammdaten!C11="Ja",G16*Stammdaten!C12,0) | I16: =G16+H16
B17: 2 | C17: =Kostenarten!C7 | D17: =Kostenarten!G7 | E17: =Kostenarten!H7 | F17: =Kostenarten!I7 | G17: =Kostenarten!G7*Kostenarten!I7 | H17: =IF(Stammdaten!C11="Ja",G17*Stammdaten!C12,0) | I17: =G17+H17
B18: 3 | C18: =Kostenarten!C8 | D18: =Kostenarten!G8 | E18: =Kostenarten!H8 | F18: =Kostenarten!I8 | G18: =Kostenarten!G8*Kostenarten!I8 | H18: =IF(Stammdaten!C11="Ja",G18*Stammdaten!C12,0) | I18: =G18+H18
B19: 4 | C19: =Kostenarten!C9 | D19: =Kostenarten!G9 | E19: =Kostenarten!H9 | F19: =Kostenarten!I9 | G19: =Kostenarten!G9*Kostenarten!I9 | H19: =IF(Stammdaten!C11="Ja",G19*Stammdaten!C12,0) | I19: =G19+H19
B20: 5 | C20: =Kostenarten!C10 | D20: =Kostenarten!G10 | E20: =Kostenarten!H10 | F20: =Kostenarten!I10 | G20: =Kostenarten!G10*Kostenarten!I10 | H20: =IF(Stammdaten!C11="Ja",G20*Stammdaten!C12,0) | I20: =G20+H20
B21: 6 | C21: =Kostenarten!C11 | D21: =Kostenarten!G11 | E21: =Kostenarten!H11 | F21: =Kostenarten!I11 | G21: =Kostenarten!G11*Kostenarten!I11 | H21: =IF(Stammdaten!C11="Ja",G21*Stammdaten!C12,0) | I21: =G21+H21
B22: 7 | C22: =Kostenarten!C12 | D22: =Kostenarten!G12 | E22: =Kostenarten!H12 | F22: =Kostenarten!I12 | G22: =Kostenarten!G12*Kostenarten!I12 | H22: =IF(Stammdaten!C11="Ja",G22*Stammdaten!C12,0) | I22: =G22+H22
B23: 8 | C23: =Kostenarten!C13 | D23: =Kostenarten!G13 | E23: =Kostenarten!H13 | F23: =Kostenarten!I13 | G23: =Kostenarten!G13*Kostenarten!I13 | H23: =IF(Stammdaten!C11="Ja",G23*Stammdaten!C12,0) | I23: =G23+H23
B24: 9 | C24: =Kostenarten!C14 | D24: =Kostenarten!G14 | E24: =Kostenarten!H14 | F24: =Kostenarten!I14 | G24: =Kostenarten!G14*Kostenarten!I14 | H24: =IF(Stammdaten!C11="Ja",G24*Stammdaten!C12,0) | I24: =G24+H24
B25: 10 | C25: =Kostenarten!C15 | D25: =Kostenarten!G15 | E25: =Kostenarten!H15 | F25: =Kostenarten!I15 | G25: =Kostenarten!G15*Kostenarten!I15 | H25: =IF(Stammdaten!C11="Ja",G25*Stammdaten!C12,0) | I25: =G25+H25
B26: 11 | C26: =Kostenarten!C16 | D26: =Kostenarten!G16 | E26: =Kostenarten!H16 | F26: =Kostenarten!I16 | G26: =Kostenarten!G16*Kostenarten!I16 | H26: =IF(Stammdaten!C11="Ja",G26*Stammdaten!C12,0) | I26: =G26+H26
B27: 12 | C27: =Kostenarten!C17 | D27: =Kostenarten!G17 | E27: =Kostenarten!H17 | F27: =Kostenarten!I17 | G27: =Kostenarten!G17*Kostenarten!I17 | H27: =IF(Stammdaten!C11="Ja",G27*Stammdaten!C12,0) | I27: =G27+H27
B28: 13 | C28: =Kostenarten!C18 | D28: =Kostenarten!G18 | E28: =Kostenarten!H18 | F28: =Kostenarten!I18 | G28: =Kostenarten!G18*Kostenarten!I18 | H28: =IF(Stammdaten!C11="Ja",G28*Stammdaten!C12,0) | I28: =G28+H28
B29: 14 | C29: =Kostenarten!C19 | D29: =Kostenarten!G19 | E29: =Kostenarten!H19 | F29: =Kostenarten!I19 | G29: =Kostenarten!G19*Kostenarten!I19 | H29: =IF(Stammdaten!C11="Ja",G29*Stammdaten!C12,0) | I29: =G29+H29
B30: 15 | C30: =Kostenarten!C20 | D30: =Kostenarten!G20 | E30: =Kostenarten!H20 | F30: =Kostenarten!I20 | G30: =Kostenarten!G20*Kostenarten!I20 | H30: =IF(Stammdaten!C11="Ja",G30*Stammdaten!C12,0) | I30: =G30+H30
B31: 16 | C31: =Kostenarten!C21 | D31: =Kostenarten!G21 | E31: =Kostenarten!H21 | F31: =Kostenarten!I21 | G31: =Kostenarten!G21*Kostenarten!I21 | H31: =IF(Stammdaten!C11="Ja",G31*Stammdaten!C12,0) | I31: =G31+H31
B32: 17 | C32: =Kostenarten!C22 | D32: =Kostenarten!G22 | E32: =Kostenarten!H22 | F32: =Kostenarten!I22 | G32: =Kostenarten!G22*Kostenarten!I22 | H32: =IF(Stammdaten!C11="Ja",G32*Stammdaten!C12,0) | I32: =G32+H32
B33: 18 | C33: =Kostenarten!C23 | D33: =Kostenarten!G23 | E33: =Kostenarten!H23 | F33: =Kostenarten!I23 | G33: =Kostenarten!G23*Kostenarten!I23 | H33: =IF(Stammdaten!C11="Ja",G33*Stammdaten!C12,0) | I33: =G33+H33
B34: 19 | C34: =Kostenarten!C24 | D34: =Kostenarten!G24 | E34: =Kostenarten!H24 | F34: =Kostenarten!I24 | G34: =Kostenarten!G24*Kostenarten!I24 | H34: =IF(Stammdaten!C11="Ja",G34*Stammdaten!C12,0) | I34: =G34+H34
B35: 20 | C35: =Kostenarten!C25 | D35: =Kostenarten!G25 | E35: =Kostenarten!H25 | F35: =Kostenarten!I25 | G35: =Kostenarten!G25*Kostenarten!I25 | H35: =IF(Stammdaten!C11="Ja",G35*Stammdaten!C12,0) | I35: =G35+H35
B36: 21 | C36: =Kostenarten!C26 | D36: =Kostenarten!G26 | E36: =Kostenarten!H26 | F36: =Kostenarten!I26 | G36: =Kostenarten!G26*Kostenarten!I26 | H36: =IF(Stammdaten!C11="Ja",G36*Stammdaten!C12,0) | I36: =G36+H36
B37: 22 | C37: =Kostenarten!C27 | D37: =Kostenarten!G27 | E37: =Kostenarten!H27 | F37: =Kostenarten!I27 | G37: =Kostenarten!G27*Kostenarten!I27 | H37: =IF(Stammdaten!C11="Ja",G37*Stammdaten!C12,0) | I37: =G37+H37
B38: 23 | C38: =Kostenarten!C28 | D38: =Kostenarten!G28 | E38: =Kostenarten!H28 | F38: =Kostenarten!I28 | G38: =Kostenarten!G28*Kostenarten!I28 | H38: =IF(Stammdaten!C11="Ja",G38*Stammdaten!C12,0) | I38: =G38+H38
B39: 24 | C39: =Kostenarten!C29 | D39: =Kostenarten!G29 | E39: =Kostenarten!H29 | F39: =Kostenarten!I29 | G39: =Kostenarten!G29*Kostenarten!I29 | H39: =IF(Stammdaten!C11="Ja",G39*Stammdaten!C12,0) | I39: =G39+H39
C40: Zwischensumme umlagefähig | D40: =SUM(D16:D39) | G40: =SUM(G16:G39) | H40: =SUM(H16:H39) | I40: =SUM(I16:I39)
B42: Ergebnis
B43: Summe Anteil Mieter netto | C43: =G40
B44: zzgl. Umsatzsteuer | C44: =H40
...

Sheet Checkliste
B2: Checkliste vor Versand an den gewerblichen Mieter
B4: OK? | C4: Prüfpunkt | D4: Status | E4: Notiz
B5: ☐ | C5: Mietvertrag: umlagefähige Kostenarten und Schlüssel geprüft | D5: offen
B6: ☐ | C6: „Sonstige Betriebskosten“ im Vertrag konkret benannt (falls genutzt) | D6: offen
B7: ☐ | C7: Instandsetzung / Finanzierung / Leerstand nicht umgelegt | D7: offen
B8: ☐ | C8: Verwaltungskosten nur bei klarer Vereinbarung | D8: offen
B9: ☐ | C9: Obergrenzen für Instandhaltung beachtet (falls vereinbart) | D9: offen
B10: ☐ | C10: HeizkostenV / Verbrauchswerte geprüft (falls anwendbar) | D10: offen
B11: ☐ | C11: Bei Mischobjekt Wohnen/Gewerbe: Schlüssel und Trennung sauber | D11: offen
B12: ☐ | C12: WEG-Hausgeld in umlagefähig / nicht umlagefähig gesplittet | D12: offen
B13: ☐ | C13: Alle Beträge dem Abrechnungszeitraum zugeordnet | D13: offen
B14: ☐ | C14: Bei USt-Option: Nettoerfassung, Vorsteuer nicht doppelt, 19 % auf Mieteranteil | D14: offen
B15: ☐ | C15: Vorauszahlungen inkl. USt korrekt abgezogen | D15: offen
B16: ☐ | C16: Abrechnung enthält: Zeitraum, Gesamtkosten, Schlüssel, Anteil, Vorauszahlung, Saldo | D16: offen
... B19: ☐ | C19: Nachzahlung / Guthaben und Zahlungsfrist kommuniziert | D19: offen
B22: Hinweis: Diese Mappe ist eine Arbeitshilfe, keine Rechts- oder Steuerberatung.

Sheet Vorauszahlungen
B2: Vorauszahlungen – Monatsübersicht (optional)
B3: Bei schwankenden Vorauszahlungen monatsweise erfassen. Summe mit Stammdaten abgleichen.
B5: Nr | C5: Monat | D5: NK netto € | E5: USt € | F5: Brutto € | G5: Eingang / Nachweis
B6: 1 | C6: Jan | D6: =Stammdaten!$C$16 | E6: =IF(Stammdaten!$C$11="Ja",D6*Stammdaten!$C$12,0) | F6: =D6+E6
B7: 2 | C7: Feb | D7: =Stammdaten!$C$16 | E7: =IF(Stammdaten!$C$11="Ja",D7*Stammdaten!$C$12,0) | F7: =D7+E7
B8: 3 | C8: Mär | D8: =Stammdaten!$C$16 | E8: =IF(Stammdaten!$C$11="Ja",D8*Stammdaten!$C$12,0) | F8: =D8+E8
B9: 4 | C9: Apr | D9: =Stammdaten!$C$16 | E9: =IF(Stammdaten!$C$11="Ja",D9*Stammdaten!$C$12,0) | F9: =D9+E9
B10: 5 | C10: Mai | D10: =Stammdaten!$C$16 | E10: =IF(Stammdaten!$C$11="Ja",D10*Stammdaten!$C$12,0) | F10: =D10+E10
B11: 6 | C11: Jun | D11: =Stammdaten!$C$16 | E11: =IF(Stammdaten!$C$11="Ja",D11*Stammdaten!$C$12,0) | F11: =D11+E11
B12: 7 | C12: Jul | D12: =Stammdaten!$C$16 | E12: =IF(Stammdaten!$C$11="Ja",D12*Stammdaten!$C$12,0) | F12: =D12+E12
B13: 8 | C13: Aug | D13: =Stammdaten!$C$16 | E13: =IF(Stammdaten!$C$11="Ja",D13*Stammdaten!$C$12,0) | F13: =D13+E13
B14: 9 | C14: Sep | D14: =Stammdaten!$C$16 | E14: =IF(Stammdaten!$C$11="Ja",D14*Stammdaten!$C$12,0) | F14: =D14+E14
B15: 10 | C15: Okt | D15: =Stammdaten!$C$16 | E15: =IF(Stammdaten!$C$11="Ja",D15*Stammdaten!$C$12,0) | F15: =D15+E15
B16: 11 | C16: Nov | D16: =Stammdaten!$C$16 | E16: =IF(Stammdaten!$C$11="Ja",D16*Stammdaten!$C$12,0) | F16: =D16+E16
B17: 12 | C17: Dez | D17: =Stammdaten!$C$16 | E17: =IF(Stammdaten!$C$11="Ja",D17*Stammdaten!$C$12,0) | F17: =D17+E17
C18: Summe | D18: =SUM(D6:D17) | E18: =SUM(E6:E17) | F18: =SUM(F6:F17)
B20: Tipp: Weicht die Summe von Stammdaten C21/C22 ab, Vorauszahlung in Stammdaten anpassen.
